<mujoco model="husky">
    <compiler angle="radian" meshdir="mesh_mujoco/" />
    <size njmax="500" nconmax="100" />
    <asset>
        <mesh name="base_link" file="base_link.stl" />
        <mesh name="wheel" file="wheel.stl" />
        <mesh name="top_chassis" file="top_chassis.stl" />
        <mesh name="user_rail" file="user_rail.stl" />
        <mesh name="bumper" file="bumper.stl" />
        <mesh name="top_plate" file="top_plate.stl" />
        <mesh name="base" file="base.stl" />
        <mesh name="shoulder" file="shoulder.stl" />
        <mesh name="upperarm" file="upperarm.stl" />
        <mesh name="forearm" file="forearm.stl" />
        <mesh name="wrist1" file="wrist1.stl" />
        <mesh name="wrist2" file="wrist2.stl" />
        <mesh name="wrist3" file="wrist3.stl" />
        <mesh name="robotiq_ft300" file="robotiq_ft300.STL" />
        <mesh name="robotiq_ft300-G-062-COUPLING_G-50-4M6-1D6_20181119" file="robotiq_ft300-G-062-COUPLING_G-50-4M6-1D6_20181119.STL" />
        <mesh name="robotiq_85_base_link" file="robotiq_85_base_link.stl" />
        <mesh name="robotiq_85_knuckle_link" file="robotiq_85_knuckle_link.stl" />
        <mesh name="robotiq_85_finger_link" file="robotiq_85_finger_link.stl" />
        <mesh name="robotiq_85_inner_knuckle_link" file="robotiq_85_inner_knuckle_link.stl" />
        <mesh name="robotiq_85_finger_tip_link" file="robotiq_85_finger_tip_link.stl" />
    </asset>
    <worldbody>
        <geom type="mesh" contype="0" conaffinity="0" group="1" mesh="base_link" />
        <geom size="0.4937 0.28545 0.061875" pos="0 0 0.061875" type="box" />
        <geom size="0.39496 0.28545 0.051875" pos="0 0 0.175625" type="box" />
        <geom type="mesh" contype="0" conaffinity="0" group="1" mesh="top_chassis" />
        <geom pos="0.272 0 0.245" type="mesh" contype="0" conaffinity="0" group="1" mesh="user_rail" />
        <geom pos="0.48 0 0.091" type="mesh" contype="0" conaffinity="0" group="1" mesh="bumper" />
        <geom pos="-0.48 0 0.091" quat="1.32679e-06 0 0 1" type="mesh" contype="0" conaffinity="0" group="1" mesh="bumper" />
        <geom pos="0.0812 0 0.245" type="mesh" contype="0" conaffinity="0" group="1" mesh="top_plate" />
        <geom pos="0.0812 0 0.245" type="mesh" mesh="top_plate" />
        <geom pos="0.0812 0 0.245" type="mesh" contype="0" conaffinity="0" group="1" rgba="0.7 0.7 0.7 1" mesh="base" />
        <geom pos="0.0812 0 0.245" type="mesh" rgba="0.7 0.7 0.7 1" mesh="base" />
        <body name="front_left_wheel_link" pos="0.256 0.2854 0.03282">
            <inertial pos="0 0 0" quat="0.707107 0 0 0.707107" mass="2.637" diaginertia="0.04411 0.02467 0.02467" />
            <joint name="front_left_wheel" pos="0 0 0" axis="0 1 0" />
            <geom type="mesh" contype="0" conaffinity="0" group="1" mesh="wheel" />
            <geom size="0.1651 0.05715" quat="0.707107 0.707106 0 0" type="cylinder" />
        </body>
        <body name="front_right_wheel_link" pos="0.256 -0.2854 0.03282">
            <inertial pos="0 0 0" quat="0.707107 0 0 0.707107" mass="2.637" diaginertia="0.04411 0.02467 0.02467" />
            <joint name="front_right_wheel" pos="0 0 0" axis="0 1 0" />
            <geom type="mesh" contype="0" conaffinity="0" group="1" mesh="wheel" />
            <geom size="0.1651 0.05715" quat="0.707107 0.707106 0 0" type="cylinder" />
        </body>
        <body name="rear_left_wheel_link" pos="-0.256 0.2854 0.03282">
            <inertial pos="0 0 0" quat="0.707107 0 0 0.707107" mass="2.637" diaginertia="0.04411 0.02467 0.02467" />
            <joint name="rear_left_wheel" pos="0 0 0" axis="0 1 0" />
            <geom type="mesh" contype="0" conaffinity="0" group="1" mesh="wheel" />
            <geom size="0.1651 0.05715" quat="0.707107 0.707106 0 0" type="cylinder" />
        </body>
        <body name="rear_right_wheel_link" pos="-0.256 -0.2854 0.03282">
            <inertial pos="0 0 0" quat="0.707107 0 0 0.707107" mass="2.637" diaginertia="0.04411 0.02467 0.02467" />
            <joint name="rear_right_wheel" pos="0 0 0" axis="0 1 0" />
            <geom type="mesh" contype="0" conaffinity="0" group="1" mesh="wheel" />
            <geom size="0.1651 0.05715" quat="0.707107 0.707106 0 0" type="cylinder" />
        </body>
        <body name="ur5/shoulder_link" pos="0.0812 0 0.334159">
            <inertial pos="0 0 0" mass="3.7" diaginertia="0.0102675 0.0102675 0.00666" />
            <joint name="ur5/shoulder_pan_joint" pos="0 0 0" axis="0 0 1" limited="true" range="-6.28319 6.28319" />
            <geom type="mesh" contype="0" conaffinity="0" group="1" rgba="0.7 0.7 0.7 1" mesh="shoulder" />
            <geom type="mesh" rgba="0.7 0.7 0.7 1" mesh="shoulder" />
            <body name="ur5/upper_arm_link" pos="0 0.13585 0" quat="0.707107 0 0.707107 0">
                <inertial pos="0 0 0.28" mass="8.393" diaginertia="0.226891 0.226891 0.0151074" />
                <joint name="ur5/shoulder_lift_joint" pos="0 0 0" axis="0 1 0" limited="true" range="-6.28319 6.28319" />
                <geom type="mesh" contype="0" conaffinity="0" group="1" rgba="0.7 0.7 0.7 1" mesh="upperarm" />
                <geom type="mesh" rgba="0.7 0.7 0.7 1" mesh="upperarm" />
                <body name="ur5/forearm_link" pos="0 -0.1197 0.425">
                    <inertial pos="0 0 0.196125" mass="2.275" diaginertia="0.0312168 0.0312168 0.004095" />
                    <joint name="ur5/elbow_joint" pos="0 0 0" axis="0 1 0" limited="true" range="-3.14159 3.14159" />
                    <geom type="mesh" contype="0" conaffinity="0" group="1" rgba="0.7 0.7 0.7 1" mesh="forearm" />
                    <geom type="mesh" rgba="0.7 0.7 0.7 1" mesh="forearm" />
                    <body name="ur5/wrist_1_link" pos="0 0 0.39225" quat="0.707107 0 0.707107 0">
                        <inertial pos="0 0.093 0" mass="1.219" diaginertia="0.0025599 0.0025599 0.0021942" />
                        <joint name="ur5/wrist_1_joint" pos="0 0 0" axis="0 1 0" limited="true" range="-6.28319 6.28319" />
                        <geom type="mesh" contype="0" conaffinity="0" group="1" rgba="0.7 0.7 0.7 1" mesh="wrist1" />
                        <geom type="mesh" rgba="0.7 0.7 0.7 1" mesh="wrist1" />
                        <body name="ur5/wrist_2_link" pos="0 0.093 0">
                            <inertial pos="0 0 0.09465" mass="1.219" diaginertia="0.0025599 0.0025599 0.0021942" />
                            <joint name="ur5/wrist_2_joint" pos="0 0 0" axis="0 0 1" limited="true" range="-6.28319 6.28319" />
                            <geom type="mesh" contype="0" conaffinity="0" group="1" rgba="0.7 0.7 0.7 1" mesh="wrist2" />
                            <geom type="mesh" rgba="0.7 0.7 0.7 1" mesh="wrist2" />
                            <body name="ur5/wrist_3_link" pos="0 0 0.09465">
                                <inertial pos="2.00096e-05 0.117773 9.62321e-06" quat="0.707428 0.706785 -7.0013e-05 -0.000114123" mass="1.15384" diaginertia="0.00225767 0.0021929 0.000745625" />
                                <joint name="ur5/wrist_3_joint" pos="0 0 0" axis="0 1 0" limited="true" range="-6.28319 6.28319" />
                                <geom type="mesh" contype="0" conaffinity="0" group="1" rgba="0.7 0.7 0.7 1" mesh="wrist3" />
                                <geom type="mesh" rgba="0.7 0.7 0.7 1" mesh="wrist3" />
                                <geom size="0.005 0.005 0.005" pos="0 0.0723 0" quat="0.707107 0 0 0.707107" type="box" />
                                <geom pos="0 0.0823 0" quat="0.5 -0.5 -0.5 -0.5" type="mesh" contype="0" conaffinity="0" group="1" rgba="0.4 0.4 0.4 1" mesh="robotiq_ft300-G-062-COUPLING_G-50-4M6-1D6_20181119" />
                                <geom pos="0 0.0823 0" quat="0.5 -0.5 -0.5 -0.5" type="mesh" rgba="0.4 0.4 0.4 1" mesh="robotiq_ft300-G-062-COUPLING_G-50-4M6-1D6_20181119" />
                                <geom pos="0 0.1238 0" quat="0.5 0.5 0.5 -0.5" type="mesh" contype="0" conaffinity="0" group="1" rgba="0.2 0.2 0.2 1" mesh="robotiq_ft300" />
                                <geom pos="0 0.1238 0" quat="0.5 0.5 0.5 -0.5" type="mesh" rgba="0.2 0.2 0.2 1" mesh="robotiq_ft300" />
                                <geom pos="0 0.1238 0" quat="-0.5 0.5 0.5 -0.5" type="mesh" contype="0" conaffinity="0" group="1" mesh="robotiq_85_base_link" />
                                <geom pos="0 0.1238 0" quat="-0.5 0.5 0.5 -0.5" type="mesh" mesh="robotiq_85_base_link" />
                                <body name="gripper_finger1_knuckle_link" pos="0 0.178705 -0.0306011" quat="-0.5 -0.5 -0.5 -0.5">
                                    <inertial pos="-0.00243606 -0.0187741 0" quat="0.647436 0.284299 -0.647436 0.284299" mass="0.0458" diaginertia="4.11145e-05 2.69913e-05 1.81232e-05" />
                                    <joint name="gripper_finger1_joint" pos="0 0 0" axis="0 0 1" limited="true" range="0 0.804" />
                                    <geom type="mesh" contype="0" conaffinity="0" group="1" mesh="robotiq_85_knuckle_link" />
                                    <geom type="mesh" mesh="robotiq_85_knuckle_link" />
                                    <geom pos="-0.00408552 -0.031486 0" type="mesh" contype="0" conaffinity="0" group="1" mesh="robotiq_85_finger_link" />
                                    <geom pos="-0.00408552 -0.031486 0" type="mesh" mesh="robotiq_85_finger_link" />
                                </body>
                                <body name="gripper_finger2_knuckle_link" pos="0 0.178705 0.0306011" quat="-0.5 0.5 0.5 -0.5">
                                    <inertial pos="-0.00243606 -0.0187741 0" quat="0.647436 0.284299 -0.647436 0.284299" mass="0.0458" diaginertia="4.11145e-05 2.69913e-05 1.81232e-05" />
                                    <joint name="gripper_finger2_joint" pos="0 0 0" axis="0 0 1" limited="true" range="-3.14 3.14" />
                                    <geom type="mesh" contype="0" conaffinity="0" group="1" mesh="robotiq_85_knuckle_link" />
                                    <geom type="mesh" mesh="robotiq_85_knuckle_link" />
                                    <geom pos="-0.00408552 -0.031486 0" type="mesh" contype="0" conaffinity="0" group="1" mesh="robotiq_85_finger_link" />
                                    <geom pos="-0.00408552 -0.031486 0" type="mesh" mesh="robotiq_85_finger_link" />
                                </body>
                                <body name="gripper_finger1_inner_knuckle_link" pos="0 0.18522 -0.0127" quat="-0.5 -0.5 -0.5 -0.5">
                                    <inertial pos="0 0 0" quat="0.707107 0.707107 0 0" mass="0.029951" diaginertia="3.9e-05 3.5e-05 5e-06" />
                                    <joint name="gripper_finger1_inner_knuckle_joint" pos="0 0 0" axis="0 0 1" limited="true" range="-3.14 3.14" />
                                    <geom type="mesh" contype="0" conaffinity="0" group="1" mesh="robotiq_85_inner_knuckle_link" />
                                    <geom type="mesh" mesh="robotiq_85_inner_knuckle_link" />
                                    <body name="gripper_finger1_finger_tip_link" pos="0.0430396 -0.0375994 0">
                                        <inertial pos="0 0 0" quat="0 0.707107 0 0.707107" mass="0.019555" diaginertia="6e-06 5e-06 2e-06" />
                                        <joint name="gripper_finger1_finger_tip_joint" pos="0 0 0" axis="0 0 1" limited="true" range="-3.14 3.14" />
                                        <geom type="mesh" contype="0" conaffinity="0" group="1" mesh="robotiq_85_finger_tip_link" />
                                        <geom type="mesh" mesh="robotiq_85_finger_tip_link" />
                                    </body>
                                </body>
                                <body name="gripper_finger2_inner_knuckle_link" pos="0 0.18522 0.0127" quat="-0.5 0.5 0.5 -0.5">
                                    <inertial pos="0 0 0" quat="0.707107 0.707107 0 0" mass="0.029951" diaginertia="3.9e-05 3.5e-05 5e-06" />
                                    <joint name="gripper_finger2_inner_knuckle_joint" pos="0 0 0" axis="0 0 1" limited="true" range="-3.14 3.14" />
                                    <geom type="mesh" contype="0" conaffinity="0" group="1" mesh="robotiq_85_inner_knuckle_link" />
                                    <geom type="mesh" mesh="robotiq_85_inner_knuckle_link" />
                                    <body name="gripper_finger2_finger_tip_link" pos="0.0430396 -0.0375994 0">
                                        <inertial pos="0 0 0" quat="0 0.707107 0 0.707107" mass="0.019555" diaginertia="6e-06 5e-06 2e-06" />
                                        <joint name="gripper_finger2_finger_tip_joint" pos="0 0 0" axis="0 0 1" limited="true" range="-3.14 3.14" />
                                        <geom type="mesh" contype="0" conaffinity="0" group="1" mesh="robotiq_85_finger_tip_link" />
                                        <geom type="mesh" mesh="robotiq_85_finger_tip_link" />
                                    </body>
                                </body>
                            </body>
                        </body>
                    </body>
                </body>
            </body>
        </body>
    </worldbody>
</mujoco>
